Workbook

Sheet DashLiveExe
B99: 46059
B100: Total trade | C100: =MAXIFS( 'JOURNAL- NUM'!I:I, 'JOURNAL- NUM'!A:A, $B99 ) -> 2 | D100: Total Point | E100: =SUMIFS( 'JOURNAL- NUM'!M:M, 'JOURNAL- NUM'!A:A, $B99 ) -> -29.95 | F100: Conti trade | G100: =COUNTIFS( 'JOURNAL- NUM'!H:H, "Conti", 'JOURNAL- NUM'!A:A, ">="&$B99, 'JOURNAL- NUM'!A:A, "<"&$B99+1 ) -> 0
B101: Avg Buy | C101: =AVERAGEIFS( 'JOURNAL- NUM'!K:K, 'JOURNAL- NUM'!A:A, $B99 ) -> 115.875 | D101: Total Pat | E101: =SUMIFS( 'JOURNAL- NUM'!V:V, 'JOURNAL- NUM'!A:A, $B99 ) -> -2188.8992 | F101: Reversal Trade | G101: =COUNTIFS( 'JOURNAL- NUM'!H:H, "Reversal", 'JOURNAL- NUM'!A:A, ">="&$B99, 'JOURNAL- NUM'!A:A, "<"&$B99+1 ) -> 0
B102: Avg sell | C102: =AVERAGEIFS( 'JOURNAL- NUM'!L:L, 'JOURNAL- NUM'!A:A, $B99 ) -> 108.3875 | D102: T FC (Tax) | E102: =SUMIFS( 'JOURNAL- NUM'!S:S, 'JOURNAL- NUM'!A:A, $B99 ) -> 160 | F102: Manual Trade | G102: =COUNTIFS( 'JOURNAL- NUM'!H:H, "Manual", 'JOURNAL- NUM'!A:A, ">="&$B99, 'JOURNAL- NUM'!A:A, "<"&$B99+1 ) -> 0
B103: %Retrun | C103: =SUMIFS( 'JOURNAL- NUM'!O:O, 'JOURNAL- NUM'!A:A, $B99 ) -> -0.26602008 | D103: Avg Inv | E103: =AVERAGEIFS( 'JOURNAL- NUM'!N:N, 'JOURNAL- NUM'!A:A, $B99 ) -> 7531.875 | F103: Long trade | G103: =COUNTIFS( 'JOURNAL- NUM'!G:G, "Long", 'JOURNAL- NUM'!A:A, ">="&$B99, 'JOURNAL- NUM'!A:A, "<"&$B99+1 ) -> 0
B104: Lot | C104: =AVERAGEIFS( 'JOURNAL- NUM'!J:J, 'JOURNAL- NUM'!A:A, $B99 )/65 -> 1 | D104: Per Lot Amt | E104: =E101/C104 -> -2188.8992 | F104: Short trade | G104: =COUNTIFS( 'JOURNAL- NUM'!G:G, "Short", 'JOURNAL- NUM'!A:A, ">="&$B99, 'JOURNAL- NUM'!A:A, "<"&$B99+1 ) -> 0
B105: Max Dur | C105: =MAXIFS( 'JOURNAL- NUM'!R:R, 'JOURNAL- NUM'!A:A, $B99 ) -> 0.010393519 | D105: Min Dur | E105: =MINIFS( 'JOURNAL- NUM'!R:R, 'JOURNAL- NUM'!A:A, $B99 ) -> 0.006724537
B108: Life Time Data | G108: ATH Data
B109: Net Pt | C109: =IFERROR(__xludf.DUMMYFUNCTION("LET(col, 'JOURNAL- NUM'!Q:Q, INDEX(col, MAX(FILTER(ROW(col), col<>""""))))"),185.35700000000003) -> 185.357 | D109: Total Gain | E109: =COUNTIF('JOURNAL- NUM'!M:M,">1") -> 26 | G109: Heads | H109: AvgPT | I109: Avg Amt | J109: ATH PT | K109: ATH Amt | L109: Date
B110: Net P/L | C110: =IFERROR(__xludf.DUMMYFUNCTION("LET(col, #REF!, INDEX(col, MAX(FILTER(ROW(col), col<>""""))))"),"#REF!") -> #REF! | D110: Total Loss | E110: =COUNTIF('JOURNAL- NUM'!M:M,"<1") -> 46 | G110: Gain | H110: =LET( valCol, 'JOURNAL- NUM'!M:M, AVERAGEIF(valCol, ">1") ) -> 19.970654 | I110: =LET( valCol, 'JOURNAL- NUM'!U:U, AVERAGEIF(valCol, ">1") ) -> 1892.6025 | J110: =max('JOURNAL- NUM'!M:M) -> 47.65 | K110: =MAX('JOURNAL- NUM'!U:U) -> 6194.5 | L110: {=LET( valCol, 'JOURNAL- NUM'!U:U, dateCol, 'JOURNAL- NUM'!A:A, maxVal, MAX(valCol), INDEX(dateCol, MATCH(maxVal, valCol, 0)) )} -> 46035
B111: Net % | C111: =IFERROR(__xludf.DUMMYFUNCTION("LET(col, 'JOURNAL- NUM'!P:P, INDEX(col, MAX(FILTER(ROW(col), col<>""""))))"),1.669205013912887) -> 1.669205 | D111: Total Trade | E111: =sum(E109:E110) -> 72 | G111: Loss | H111: =LET( valCol, 'JOURNAL- NUM'!M:M, AVERAGEIF(valCol, "<1") ) -> -7.2582609 | I111: =LET( valCol, 'JOURNAL- NUM'!U:U, AVERAGEIF(valCol, "<1") ) -> -817.81304 | J111: =MIN('JOURNAL- NUM'!M:M) -> -24.8 | K111: =MIN('JOURNAL- NUM'!U:U) -> -3224 | L111: {=LET( valCol,'JOURNAL- NUM'!U:U, dateCol,'JOURNAL- NUM'!A:A, minVal, MIN(valCol), INDEX(dateCol, MATCH(minVal, valCol, 0)) )} -> 46049
B112: T. Brokrage | C112: =SUM('JOURNAL- NUM'!S:S) -> 2880 | D112: Accu % | E112: =E109/E111 -> 0.36111111
B113: T. Gov | C113: =SUM('JOURNAL- NUM'!T:T) -> 2375.6207
B114: T.FC | C114: =sum(C112:C113) -> 5255.6207
B116: Str Entry
B117: Str | C117: =OLD!$D$522 -> Conti | D117: =OLD!$D$523 -> Reversal | E117: =OLD!$D$527 -> No Record | F117: =OLD!$D$521 -> FIB ENTRY | G117: =OLD!$D$533 -> Manual | H117: Net
B118: Gain | C118: =LET( amtCol, 'JOURNAL- Disc-Temp'!$C:$C, tagCol, 'JOURNAL- Disc-Temp'!$D:$D, SUMIFS(amtCol, tagCol, "Conti", amtCol, ">0") ) -> #N/A | D118: =LET( amtCol, 'JOURNAL- Disc-Temp'!$C:$C, tagCol, 'JOURNAL- Disc-Temp'!$D:$D, SUMIFS(amtCol, tagCol, "Reversal", amtCol, ">0") ) -> #N/A | E118: =LET( amtCol, 'JOURNAL- Disc-Temp'!$C:$C, tagCol, 'JOURNAL- Disc-Temp'!$D:$D, SUMIFS(amtCol, tagCol, "No Record", amtCol, ">0") ) -> #N/A | F118: =LET( amtCol, 'JOURNAL- Disc-Temp'!$C:$C, tagCol, 'JOURNAL- Disc-Temp'!$D:$D, SUMIFS(amtCol, tagCol, "FIB ENTRY", amtCol, ">0") ) -> #N/A | G118: =LET( amtCol, 'JOURNAL- Disc-Temp'!$C:$C, tagCol, 'JOURNAL- Disc-Temp'!$D:$D, SUMIFS(amtCol, tagCol, "Manual", amtCol, ">0") ) -> #N/A | H118: =SUM(C118:G118) -> #N/A
B119: Loss | C119: =LET( amtCol, 'JOURNAL- Disc-Temp'!C:C, tagCol, 'JOURNAL- Disc-Temp'!D:D, SUMIFS(amtCol, tagCol, "Conti", amtCol, "<0") ) -> #N/A | D119: =LET( amtCol, 'JOURNAL- Disc-Temp'!$C:$C, tagCol, 'JOURNAL- Disc-Temp'!$D:$D, SUMIFS(amtCol, tagCol, "Reversal", amtCol, "<0") ) -> #N/A | E119: =LET( amtCol, 'JOURNAL- Disc-Temp'!$C:$C, tagCol, 'JOURNAL- Disc-Temp'!$D:$D, SUMIFS(amtCol, tagCol, "No Record", amtCol, "<0") ) -> #N/A | F119: =LET( amtCol, 'JOURNAL- Disc-Temp'!$C:$C, tagCol, 'JOURNAL- Disc-Temp'!$D:$D, SUMIFS(amtCol, tagCol, "FIB ENTRY", amtCol, "<0") ) -> #N/A | G119: =LET( amtCol, 'JOURNAL- Disc-Temp'!$C:$C, tagCol, 'JOURNAL- Disc-Temp'!$D:$D, SUMIFS(amtCol, tagCol, "Manual", amtCol, "<0") ) -> #N/A | H119: =SUM(C119:G119) -> #N/A
B120: Sum | C120: =sum(C118:C119) -> #N/A | D120: =sum(D118:D119) -> #N/A | E120: =sum(E118:E119) -> #N/A | F120: =sum(F118:F119) -> #N/A | G120: =sum(G118:G119) -> #N/A | H120: =SUM(C120:G120) -> #N/A
B121: Count | C121: =COUNTIF('JOURNAL- NUM'!H:H, "Conti") -> 25 | D121: =COUNTIF('JOURNAL- NUM'!$H:$H, "Reversal") -> 9 | E121: =COUNTIF('JOURNAL- NUM'!$H:$H, "No Record") -> 8 | F121: =COUNTIF('JOURNAL- NUM'!$H:$H, "FIB ENTRY") -> 2 | G121: =COUNTIF('JOURNAL- NUM'!$H:$H, "Manual") -> 11

Sheet JOURNAL- Disc
A1: Particular | B1: Mon | C1: Tue | D1: Wed | E1: Thu | F1: Fri | G1: Sat | H1: Sun
A2: Date | E2: 1 | F2: 2 | G2: 3 | H2: 4
A3: Link
A4: Amt | E4: -387 | F4: 1375
A5: Obs | F5: - jitni der me soochte ki kyakarna, dusri strategy me boom Order pad gaya!!! - fib ke premium pe entry kar raha tha - koi psycology ka tamasha nahi - jo mai cahta tha wo aaj finally ho raha!!! (64 point ka zone) approx 44% ja return!! - 100 rs ka premium me 2000 - dimag clr bahut zyada info ab process nahi - strike match ka lable sahi !!, simple elegent solution - itna bhadiya, mujhe kuch nahi karna!!!! - hands off approch ho!!, 2/3/5 pe dekh raha tha - ATR baised Trail bana diya !! ema/DEMA,FIB,LL,breakout,PP,Candle , ab to sahii hi hoga!!,Sasta prem, ATM strike, Auto order placement !! sahi hoga mai janta hun kuch anhi,!! profit hoga to bada,loss hoga to chota!! bahut bhadiya, haut bhaut bhaut bhadiya!!
A6: Date | B6: 5 | C6: 6 | D6: 7 | E6: 8 | F6: 9 | G6: 10 | H6: 11
A7: Link | B7: Kal se Lot bhadayenge!!⏰↗️↗️🏃🏻😎 | C7: https://youtu.be/p6MxwE_eP5c?si=D3FJokzw9_tJtr55 | D7: https://youtu.be/L9IgT-EXNzo?si=C8nAXYV4UGoDpR0W | F7: https://youtu.be/L9IgT-EXNzo?si=C8nAXYV4UGoDpR0W
A8: Amt | B8: -249 | C8: -2286 | D8: -3152 | E8: 4927 | F8: 15
A9: Obs | B9: - auto fib me doubt ho raha - LL pe entry, Reversal Algo leak, turant square off !! - prem pe auto fire, samajh aaya ki ye scaleble/predictable nahi hai - long/short auto candle ho gayi - US SAMAY KYA KAR RAHE THEY!!! itna zyada code me nahi define kar sakta, jo hai yahi hai, - lot multiplier add kar diya - entry kun nahi aay!!!, red ke baad turant Green to invalid, visually dikh raha, finally clr!! - 3 min me proper entry aayi!!, par mai pehle hi bhasam ho jaata hun!! - table bhi bana di thi, -index me bol den ki kahan entry,/exit , khud bana diya jo broker nahi dete - sell ke failed order se se test kar raha tha -22 se ye mat samjhe ki chota hai !! - saari hi sahi, har me trade lene ke chakkar me nahi aana | C9: video nahi record hua! | E9: - Pehli baar computer band pe trade - Pehli baar 5000 tak profit dekha! | F9: 500% tarrif dhanmki
A10: Date | B10: 12 | C10: 13 | D10: 14 | E10: 15 | F10: 16 | G10: 17 | H10: 18
A11: Link | B11: https://youtu.be/rEEYsxw6xkg?si=JXSIyk4-8MS2XfF9 | C11: lag raha hai, ab baat ban rahi hai!🧪😀😎🤖 | D11: https://youtu.be/kyoVAyp5s6s?si=JWRWHefJHXene8sv | E11: - | F11: kya se kya ho gaya dekhte dekhte !!😁🎯😎
A12: Amt | B12: 1968 | C12: 1490 | D12: 6101 | E12: - | F12: 4326
A13: Obs | C13: - lekage | D13: - sabhai se baat +3000 ja kar palat aaya | E13: Mumbai me BMC election
A14: Date | B14: 19 | C14: 20 | D14: 21 | E14: 22 | F14: 23 | G14: 24 | H14: 25
A15: Link | C15: https://youtu.be/WBEo5XEM9hA
A16: Amt | B16: -8595 | C16: -667 | D16: -1317 | E16: 2355 | F16: 3451
A17: Obs | C17: -reversal ka lot kam kar diya - continuation ko 2 - pehli baar , confident nahi to size kam_conti me - single candle me 1700 -> seedhe negative! - Algo time se exit kara deta !! - 1.3% index Gira Code - Use Fresh Zone on kar liya - USe auto aur manual Strike Use karna start! | D17: - bahut der tak baitha tha mai!! - feel ki algo late karta hai, maual ke liye kuch banao! -Din bhar light ne tamash kiya, Move miss par Ipad aur mobile pe record Pipleline Clr - 12:30 aur entry nahi mili - jald bazi me 2 min pe li li, dikha ki 2/3 me me DEMA alag alag dikhta hai - bahut desperate ho raha, dil kar raha tha, haath se order punch karo!! - pura din laga entry nahi aayi,par PC pe dekha to kai jagha entry thi Code - Dono me short-Short likh diya to entyr nahi aayi thi | E17: - Introducing Multi TF EQ Curve, and DashBoard - Excel me bhaut heavy forumle banane aa gaye!! | F17: -video jaldi upload kiya kijeye - continuation ki entry, kaafi der baithata fir fata! - ghar nikalna tha - baad me call karte hai,video edit karna , light nahi aa rahi
A18: Date | B18: 26 | C18: 27 | D18: 28 | E18: 29 | F18: 30 | G18: 31 | H18: 1
A19: Amt | B19: - | C19: -3289 | D19: -444 | E19: -711 | F19: 2284
A20: Link | B20: -
A21: Obs | B21: Independence day holiday | C21: - 3 v shape bane -9:28 pe bahut conviction ki manual entry, sahi bhi thi wo - 1:32 fir mann bol raha tha, manual., par nahi, sahi kiya !! - EU deal Sign ho gayi, tab Reversal Alert nahi baja tha!itnaaa fast move aaya tha!!! | D21: - fir lag raha tha , manual le le, test kar raha, tha ki auto SL kahan lagayenge!! Fib/LineVased aaram se entry aayi thi - kal ke loss ke barabar, aaj usse zyada hi le kar jaana hai - 42 min tak baitha tha lag raha tha engulfing, par EMA,Zone,kain to ruke ga!! - +4200 dikha kar palat gaya!!, 2 candle me, bahut bura lag raha tha!! Code - Manual target aur exit ke liye code kiya ! | E21: - 9 Trade Le daale - Aaj sach me kismat aur Algo power ki Gross me profit me they!! - Trump Possible Attack Iran, Lincon Armada -Mere saamne price inc irritattion ki algo me signal nahi, - Tv ke buy/Sell button ko test kar raa - Mind bahut panic, 1-3 ke alert, galti se 3 lot ka order - Ye to easy moeny hai - pagla kar 9 trade le daale - very embarassed | F21: - GoodNotes ka syn Clr -Daily summary, ipad mind maps -BRD start kar diya -organise kar ke Code develop karenge -realise hua ki TV char pe hi sell order -partial lot booking - accha feel aa raha, 3 min pehle alert bajta, to tayyar aur setup karne ka mauka mil jaata | G21: - Silver Gold Crashed!! - Code se hi Sheet me cal, Brokrage/Tax - Jan ki summary - Discriptive, ye calander based view me Observation Record | H21: Budget presnt hoga

Sheet JOURNAL- NUM
A1: Date | B1: Week | C1: unique ID | D1: BUY Time | E1: SELL Time | F1: Strike | G1: L/S | H1: STR Entry | I1: Trade | J1: Qty | K1: BUY | L1: SELL | M1: Pt | N1: Invested | O1: % Return | P1: C% | Q1: C Pt | R1: Dur | S1: {=LET( data, IF( K2:K79="", , LET( buy, K2:K79, sell, L2:L79, qty, J2:J79, brokerage, qty*0+40, stt, (sell*qty)*0.001, exch, (buy*qty + sell*qty)*0.0003503, stamp, (buy*qty)*0.00003, gst, (brokerage + exch + stamp)*0.18, otherCharges, stt + exch + stamp + gst, grossPL, (sell-buy)*qty, netPL, grossPL - (brokerage + otherCharges), HSTACK(brokerage, otherCharges, grossPL, netPL) ) ), VSTACK( {"Brokerage","Other Charges","Gross P/L","Net P/L"}, IFERROR(data,"") ) )} -> Brokerage | T1: Other Charges | U1: Gross P/L | V1: Net P/L | W1: Total FC | X1: TF | Y1: High | Z1: Low | AA1: Runn | AB1: DD
A2: 46023 | B2: W1 | C2: =TEXTJOIN( " | ", TRUE, TEXT(A2,"ddd dd - mmm"), TEXT(D2,"hh:mm"), G2, TEXT(I2,"0") ) -> Thu 01 - Jan | 14:50 | No Record | 1 | D2: 0.61834491 | E2: 0.6250463 | F2: NIFTY 06 JAN 26150 PUT | G2: No Record | H2: No Record | I2: 1 | J2: 65 | K2: 69.15 | L2: 65.05 | M2: =L2-K2 -> -4.1 | N2: =K2*J2 -> 4494.75 | O2: =M2/K2 -> -0.059291396 | P2: =O2 -> -0.059291396 | Q2: =M2 -> -4.1 | R2: =E2-D2 -> 0.0067013889 | S2: 40 | T2: 15.193051 | U2: -266.5 | V2: -321.69305 | W2: =T2+S2 -> 55.193051
A3: 46023 | B3: W1 | C3: =TEXTJOIN( " | ", TRUE, TEXT(A3,"ddd dd - mmm"), TEXT(D3,"hh:mm"), G3, TEXT(I3,"0") ) -> Thu 01 - Jan | 15:15 | No Record | 2 | D3: 0.63561343 | E3: 0.63710648 | F3: NIFTY 06 JAN 26150 PUT | G3: No Record | H3: No Record | I3: 2 | J3: 65 | K3: 71.6 | L3: 71.45 | M3: =L3-K3 -> -0.15 | N3: =K3*J3 -> 4654 | O3: =M3/K3 -> -0.0020949721 | P3: =O3+P2 -> -0.061386368 | Q3: =M3+Q2 -> -4.25 | R3: =E3-D3 -> 0.0014930556 | S3: 40 | T3: 15.85247 | U3: -9.75 | V3: -65.60247 | W3: =T3+S3 -> 55.85247
A4: 46024 | B4: W1 | C4: =TEXTJOIN( " | ", TRUE, TEXT(A4,"ddd dd - mmm"), TEXT(D4,"hh:mm"), G4, TEXT(I4,"0") ) -> Fri 02 - Jan | 09:17 | Short | 1 | D4: 0.3868287 | E4: 0.3909838 | F4: NIFTY 06 JAN 26200 PUT | G4: Short | H4: FIB ENTRY | I4: 1 | J4: 65 | K4: 71.75 | L4: 65.35 | M4: =L4-K4 -> -6.4 | N4: =K4*J4 -> 4663.75 | O4: =M4/K4 -> -0.089198606 | P4: =O4 -> -0.089198606 | Q4: =M4+Q3 -> -10.65 | R4: =E4-D4 -> 0.0041550926 | S4: 40 | T4: 15.296451 | U4: -416 | V4: -471.29645 | W4: =T4+S4 -> 55.296451
A5: 46024 | B5: W1 | C5: =TEXTJOIN( " | ", TRUE, TEXT(A5,"ddd dd - mmm"), TEXT(D5,"hh:mm"), G5, TEXT(I5,"0") ) -> Fri 02 - Jan | 09:25 | Long | 2 | D5: 0.39238426 | E5: 0.40611111 | F5: NIFTY 06 JAN 26200 CALL | G5: Long | H5: Conti | I5: 2 | J5: 65 | K5: 77.3 | L5: 111.6 | M5: =L5-K5 -> 34.3 | N5: =K5*J5 -> 5024.5 | O5: =M5/K5 -> 0.44372574 | P5: =O5+P4 -> 0.35452714 | Q5: =M5+Q4 -> 23.65 | R5: =E5-D5 -> 0.013726852 | S5: 40 | T5: 19.707234 | U5: 2229.5 | V5: 2169.7928 | W5: =T5+S5 -> 59.707234
A6: 46024 | B6: W1 | C6: =TEXTJOIN( " | ", TRUE, TEXT(A6,"ddd dd - mmm"), TEXT(D6,"hh:mm"), G6, TEXT(I6,"0") ) -> Fri 02 - Jan | 10:57 | Short | 3 | D6: 0.45628472 | E6: 0.47503472 | F6: NIFTY 06 JAN 26250 PUT | G6: Short | H6: Reversal | I6: 3 | J6: 65 | K6: 59.75 | L6: 55.6 | M6: =L6-K6 -> -4.15 | N6: =K6*J6 -> 3883.75 | O6: =M6/K6 -> -0.069456067 | P6: =O6+P5 -> 0.28507107 | Q6: =M6+Q5 -> 19.5 | R6: =E6-D6 -> 0.01875 | S6: 40 | T6: 14.05071 | U6: -269.75 | V6: -323.80071 | W6: =T6+S6 -> 54.05071
A7: 46027 | B7: W2 | C7: =TEXTJOIN( " | ", TRUE, TEXT(A7,"ddd dd - mmm"), TEXT(D7,"hh:mm"), G7, TEXT(I7,"0") ) -> Mon 05 - Jan | 09:36 | Short | 1 | D7: 0.40003472 | E7: 0.40038194 | F7: NIFTY 06 JAN 26300 PUT | G7: Short | H7: Reversal | I7: 1 | J7: 65 | K7: 71.35 | L7: 74.9 | M7: =L7-K7 -> 3.55 | N7: =K7*J7 -> 4637.75 | O7: =M7/K7 -> 0.04975473 | P7: =O7+P6 -> 0.3348258 | Q7: =M7+Q6 -> 23.05 | R7: =E7-D7 -> 0.00034722222 | S7: 40 | T7: 16.162123 | U7: 230.75 | V7: 174.58788 | W7: =T7+S7 -> 56.162123
A8: 46027 | B8: W2 | C8: =TEXTJOIN( " | ", TRUE, TEXT(A8,"ddd dd - mmm"), TEXT(D8,"hh:mm"), G8, TEXT(I8,"0") ) -> Mon 05 - Jan | 09:50 | Long | 2 | D8: 0.40975694 | E8: 0.41443287 | F8: NIFTY 06 JAN 26300 CALL | G8: Long | H8: FIB ENTRY | I8: 2 | J8: 65 | K8: 61.8 | L8: 72.65 | M8: =L8-K8 -> 10.85 | N8: =K8*J8 -> 4017 | O8: =M8/K8 -> 0.17556634 | P8: =O8+P7 -> 0.51039214 | Q8: =M8+Q7 -> 33.9 | R8: =E8-D8 -> 0.0046759259 | S8: 40 | T8: 15.676856 | U8: 705.25 | V8: 649.57314 | W8: =T8+S8 -> 55.676856
A9: 46027 | B9: W2 | C9: =TEXTJOIN( " | ", TRUE, TEXT(A9,"ddd dd - mmm"), TEXT(D9,"hh:mm"), G9, TEXT(I9,"0") ) -> Mon 05 - Jan | 10:12 | Short | 3 | D9: 0.42501157 | E9: 0.42503472 | F9: NIFTY 06 JAN 26300 PUT | G9: Short | H9: Reversal | I9: 3 | J9: 65 | K9: 42.75 | L9: 42.7 | M9: =L9-K9 -> -0.05 | N9: =K9*J9 -> 2778.75 | O9: =M9/K9 -> -0.0011695906 | P9: =O9+P8 -> 0.50922255 | Q9: =M9+Q8 -> 33.85 | R9: =E9-D9 -> 2.3148148e-05 | S9: 40 | T9: 12.369739 | U9: -3.25 | V9: -55.619739 | W9: =T9+S9 -> 52.369739
A10: 46027 | B10: W2 | C10: =TEXTJOIN( " | ", TRUE, TEXT(A10,"ddd dd - mmm"), TEXT(D10,"hh:mm"), G10, TEXT(I10,"0") ) -> Mon 05 - Jan | 10:43 | Short | 4 | D10: 0.44653935 | E10: 0.44863426 | F10: NIFTY 06 JAN 26350 PUT | G10: Short | H10: No Record | I10: 4 | J10: 65 | K10: 60.75 | L10: 53.1 | M10: =L10-K10 -> -7.65 | N10: =K10*J10 -> 3948.75 | O10: =M10/K10 -> -0.12592593 | P10: =O10+P9 -> 0.38329663 | Q10: =M10+Q9 -> 26.2 | R10: =E10-D10 -> 0.0020949074 | S10: 40 | T10: 13.850209 | U10: -497.25 | V10: -551.10021 | W10: =T10+S10 -> 53.850209
A11: 46027 | B11: W2 | C11: =TEXTJOIN( " | ", TRUE, TEXT(A11,"ddd dd - mmm"), TEXT(D11,"hh:mm"), G11, TEXT(I11,"0") ) -> Mon 05 - Jan | 11:00 | Short | 5 | D11: 0.45840278 | E11: 0.46045139 | F11: NIFTY 06 JAN 26350 PUT | G11: Short | H11: No Record | I11: 5 | J11: 65 | K11: 54.9 | L11: 48.55 | M11: =L11-K11 -> -6.35 | N11: =K11*J11 -> 3568.5 | O11: =M11/K11 -> -0.11566485 | P11: =O11+P10 -> 0.26763178 | Q11: =M11+Q10 -> 19.85 | R11: =E11-D11 -> 0.0020486111 | S11: 40 | T11: 13.261571 | U11: -412.75 | V11: -466.01157 | W11: =T11+S11 -> 53.261571
A12: 46028 | B12: W2 | C12: =TEXTJOIN( " | ", TRUE, TEXT(A12,"ddd dd - mmm"), TEXT(D12,"hh:mm"), G12, TEXT(I12,"0") ) -> Tue 06 - Jan | 10:22 | Short | 1 | D12: 0.43229167 | E12: 0.43930556 | F12: NIFTY 13 JAN 26250 PUT | G12: Short | H12: No Record | I12: 1 | J12: 65 | K12: 108.45 | L12: 105.65 | M12: =L12-K12 -> -2.8 | N12: =K12*J12 -> 7049.25 | O12: =M12/K12 -> -0.025818349 | P12: =O12+P11 -> 0.24181343 | Q12: =M12+Q11 -> 17.05 | R12: =E12-D12 -> 0.0070138889 | S12: 40 | T12: 20.069234 | U12: -182 | V12: -242.06923 | W12: =T12+S12 -> 60.069234
A13: 46028 | B13: W2 | C13: =TEXTJOIN( " | ", TRUE, TEXT(A13,"ddd dd - mmm"), TEXT(D13,"hh:mm"), G13, TEXT(I13,"0") ) -> Tue 06 - Jan | 10:25 | Short | 2 | D13: 0.4340625 | E13: 0.43930556 | F13: NIFTY 13 JAN 26250 PUT | G13: Short | H13: No Record | I13: 2 | J13: 130 | K13: 112.85 | L13: 105.65 | M13: =L13-K13 -> -7.2 | N13: =K13*J13 -> 14670.5 | O13: =M13/K13 -> -0.063801506 | P13: =O13+P12 -> 0.17801193 | Q13: =M13+Q12 -> 9.85 | R13: =E13-D13 -> 0.0052430556 | S13: 40 | T13: 33.195156 | U13: -936 | V13: -1009.1952 | W13: =T13+S13 -> 73.195156
A14: 46028 | B14: W2 | C14: =TEXTJOIN( " | ", TRUE, TEXT(A14,"ddd dd - mmm"), TEXT(D14,"hh:mm"), G14, TEXT(I14,"0") ) -> Tue 06 - Jan | 10:36 | Short | 3 | D14: 0.44200231 | E14: 0.44592593 | F14: NIFTY 13 JAN 26250 PUT | G14: Short | H14: No Record | I14: 3 | J14: 65 | K14: 113.05 | L14: 114.95 | M14: =L14-K14 -> 1.9 | N14: =K14*J14 -> 7348.25 | O14: =M14/K14 -> 0.016806723 | P14: =O14+P13 -> 0.19481865 | Q14: =M14+Q13 -> 11.75 | R14: =E14-D14 -> 0.0039236111 | S14: 40 | T14: 21.057784 | U14: 123.5 | V14: 62.442216 | W14: =T14+S14 -> 61.057784
A15: 46028 | B15: W2 | C15: =TEXTJOIN( " | ", TRUE, TEXT(A15,"ddd dd - mmm"), TEXT(D15,"hh:mm"), G15, TEXT(I15,"0") ) -> Tue 06 - Jan | 10:55 | Long | 4 | D15: 0.45488426 | E15: 0.45818287 | F15: NIFTY 13 JAN 26250 CALL | G15: Long | H15: No Record | I15: 4 | J15: 130 | K15: 127.5 | L15: 119.65 | M15: =L15-K15 -> -7.85 | N15: =K15*J15 -> 16575 | O15: =M15/K15 -> -0.061568627 | P15: =O15+P14 -> 0.13325002 | Q15: =M15+Q14 -> 3.9 | R15: =E15-D15 -> 0.0032986111 | S15: 40 | T15: 36.622112 | U15: -1020.5 | V15: -1097.1221 | W15: =T15+S15 -> 76.622112
A16: 46029 | B16: W2 | C16: =TEXTJOIN( " | ", TRUE, TEXT(A16,"ddd dd - mmm"), TEXT(D16,"hh:mm"), G16, TEXT(I16,"0") ) -> Wed 07 - Jan | 10:04 | Short | 1 | D16: 0.42010417 | E16: 0.4272338 | F16: NIFTY 13 JAN 26150 PUT | G16: Short | H16: Manual | I16: 1 | J16: 130 | K16: 93.45 | L16: 77.7 | M16: =L16-K16 -> -15.75 | N16: =K16*J16 -> 12148.5 | O16: =M16/K16 -> -0.16853933 | P16: =O16+P15 -> -0.035289304 | Q16: =M16+Q15 -> -11.85 | R16: =E16-D16 -> 0.0071296296 | S16: 40 | T16: 26.927977 | U16: -2047.5 | V16: -2114.428 | W16: =T16+S16 -> 66.927977
... A41: 46044 | B41: W4 | C41: =TEXTJOIN( " | ", TRUE, TEXT(A41,"ddd dd - mmm"), TEXT(D41,"hh:mm"), G41, TEXT(I41,"0") ) -> Thu 22 - Jan | 09:58 | Short | 1 | D41: 0.41548611 | E41: 0.43947917 | F41: NIFTY 27 JAN 25150 PUT | G41: Short | H41: Reversal | I41: 1 | J41: 65 | K41: 52.8 | L41: 89.9 | M41: =L41-K41 -> 37.1 | N41: =K41*J41 -> 3432 | O41: =M41/K41 -> 0.70265152 | P41: =O41+P40 -> 1.4424286 | Q41: =M41+Q40 -> 130.357 | R41: =E41-D41 -> 0.023993056 | S41: 40 | T41: 16.999058 | U41: 2411.5 | V41: 2354.5009 | W41: =T41+S41 -> 56.999058
A42: 46045 | B42: W4 | C42: =TEXTJOIN( " | ", TRUE, TEXT(A42,"ddd dd - mmm"), TEXT(D42,"hh:mm"), G42, TEXT(I42,"0") ) -> Fri 23 - Jan | 10:57 | Short | 1 | D42: 0.4562963 | E42: 0.49017361 | F42: NIFTY 27 JAN 25250 PUT | G42: Short | H42: Conti | I42: 1 | J42: 130 | K42: 83 | L42: 110.1 | M42: =L42-K42 -> 27.1 | N42: =K42*J42 -> 10790 | O42: =M42/K42 -> 0.32650602 | P42: =O42+P41 -> 1.7689346 | Q42: =M42+Q41 -> 157.457 | R42: =E42-D42 -> 0.033877315 | S42: 40 | T42: 32.271391 | U42: 3523 | V42: 3450.7286 | W42: =T42+S42 -> 72.271391 | X42: 3
A43: 46049 | B43: W4 | C43: =TEXTJOIN( " | ", TRUE, TEXT(A43,"ddd dd - mmm"), TEXT(D43,"hh:mm"), G43, TEXT(I43,"0") ) -> Tue 27 - Jan | 12:06 | Long | 1 | D43: 0.50418981 | E43: 0.52107639 | F43: NIFTY 27 JAN 25100 CALL | G43: Long | H43: Conti | I43: 1 | J43: 130 | K43: 90.3 | L43: 65.5 | M43: =L43-K43 -> -24.8 | N43: =K43*J43 -> 11739 | O43: =M43/K43 -> -0.27464009 | P43: =O43+P42 -> 1.4942945 | Q43: =M43+Q42 -> 132.657 | R43: =E43-D43 -> 0.016886574 | S43: 40 | T43: 24.502633 | U43: -3224 | V43: -3288.5026 | W43: =T43+S43 -> 64.502633 | X43: 3
A44: 46050 | B44: W4 | C44: =TEXTJOIN( " | ", TRUE, TEXT(A44,"ddd dd - mmm"), TEXT(D44,"hh:mm"), G44, TEXT(I44,"0") ) -> Wed 28 - Jan | 10:54 | Long | 1 | D44: 0.45418981 | E44: 0.48878472 | F44: NIFTY 03 FEB 25300 CALL | G44: Long | H44: Conti | I44: 1 | J44: 130 | K44: 243.9 | L44: 241.3 | M44: =L44-K44 -> -2.6 | N44: =K44*J44 -> 31707 | O44: =M44/K44 -> -0.010660107 | P44: =O44+P43 -> 1.4836344 | Q44: =M44+Q43 -> 130.057 | R44: =E44-D44 -> 0.034594907 | S44: 40 | T44: 65.764145 | U44: -338 | V44: -443.76414 | W44: =T44+S44 -> 105.76414 | X44: 3 | Y44: 277 | Z44: 235 | AA44: =Y44-K44 -> 33.1 | AB44: =Z44-K44 -> -8.9
A45: 46051 | B45: W4 | C45: =TEXTJOIN( " | ", TRUE, TEXT(A45,"ddd dd - mmm"), TEXT(D45,"hh:mm"), G45, TEXT(I45,"0") ) -> Thu 29 - Jan | 10:02 | Short | 1 | D45: 0.41857639 | E45: 0.42101852 | F45: NIFTY 03 FEB 25050 CALL | G45: Short | H45: Manual | I45: 1 | J45: 65 | K45: 291.35 | L45: 293.2 | M45: =L45-K45 -> 1.85 | N45: =K45*J45 -> 18937.75 | O45: =M45/K45 -> 0.0063497512 | P45: =O45+P44 -> 1.4899842 | Q45: =M45+Q44 -> 131.907 | R45: =E45-D45 -> 0.0024421296 | S45: 40 | T45: 42.634092 | U45: 120.25 | V45: 37.615908 | W45: =T45+S45 -> 82.634092
A46: 46051 | B46: W4 | C46: =TEXTJOIN( " | ", TRUE, TEXT(A46,"ddd dd - mmm"), TEXT(D46,"hh:mm"), G46, TEXT(I46,"0") ) -> Thu 29 - Jan | 10:07 | Short | 2 | D46: 0.42155093 | E46: 0.42229167 | F46: NIFTY 03 FEB 25200 PUT | G46: Short | H46: Manual | I46: 2 | J46: 195 | K46: 207.6 | L46: 205.2 | M46: =L46-K46 -> -2.4 | N46: =K46*J46 -> 40482 | O46: =M46/K46 -> -0.011560694 | P46: =O46+P45 -> 1.4784235 | Q46: =M46+Q45 -> 129.507 | R46: =E46-D46 -> 0.00074074074 | S46: 40 | T46: 81.920406 | U46: -468 | V46: -589.92041 | W46: =T46+S46 -> 121.92041
A47: 46051 | B47: W4 | C47: =TEXTJOIN( " | ", TRUE, TEXT(A47,"ddd dd - mmm"), TEXT(D47,"hh:mm"), G47, TEXT(I47,"0") ) -> Thu 29 - Jan | 11:25 | Short | 3 | D47: 0.47579861 | E47: 0.47672454 | F47: NIFTY 03 FEB 25450 PUT | G47: Short | H47: Manual | I47: 3 | J47: 65 | K47: 273.1 | L47: 282.4 | M47: =L47-K47 -> 9.3 | N47: =K47*J47 -> 17751.5 | O47: =M47/K47 -> 0.03405346 | P47: =O47+P46 -> 1.5124769 | Q47: =M47+Q46 -> 138.807 | R47: =E47-D47 -> 0.00092592593 | S47: 40 | T47: 41.109583 | U47: 604.5 | V47: 523.39042 | W47: =T47+S47 -> 81.109583
A48: 46051 | B48: W4 | C48: =TEXTJOIN( " | ", TRUE, TEXT(A48,"ddd dd - mmm"), TEXT(D48,"hh:mm"), G48, TEXT(I48,"0") ) -> Thu 29 - Jan | 11:37 | Short | 4 | D48: 0.48471065 | E48: 0.48747685 | F48: NIFTY 03 FEB 25450 PUT | G48: Short | H48: Manual | I48: 4 | J48: 65 | K48: 290.65 | L48: 286.85 | M48: =L48-K48 -> -3.8 | N48: =K48*J48 -> 18892.25 | O48: =M48/K48 -> -0.013074144 | P48: =O48+P47 -> 1.4994028 | Q48: =M48+Q47 -> 135.007 | R48: =E48-D48 -> 0.0027662037 | S48: 40 | T48: 42.030311 | U48: -247 | V48: -329.03031 | W48: =T48+S48 -> 82.030311
A49: 46051 | B49: W4 | C49: =TEXTJOIN( " | ", TRUE, TEXT(A49,"ddd dd - mmm"), TEXT(D49,"hh:mm"), G49, TEXT(I49,"0") ) -> Thu 29 - Jan | 11:45 | Short | 5 | D49: 0.48993056 | E49: 0.49181713 | F49: NIFTY 03 FEB 25450 PUT | G49: Short | H49: Manual | I49: 5 | J49: 65 | K49: 289.1 | L49: 284.65 | M49: =L49-K49 -> -4.45 | N49: =K49*J49 -> 18791.5 | O49: =M49/K49 -> -0.015392598 | P49: =O49+P48 -> 1.4840102 | Q49: =M49+Q48 -> 130.557 | R49: =E49-D49 -> 0.0018865741 | S49: 40 | T49: 41.78299 | U49: -289.25 | V49: -371.03299 | W49: =T49+S49 -> 81.78299
A50: 46051 | B50: W4 | C50: =TEXTJOIN( " | ", TRUE, TEXT(A50,"ddd dd - mmm"), TEXT(D50,"hh:mm"), G50, TEXT(I50,"0") ) -> Thu 29 - Jan | 11:48 | Short | 6 | D50: 0.49219907 | E50: 0.49331019 | F50: NIFTY 03 FEB 25450 PUT | G50: Short | H50: Manual | I50: 6 | J50: 65 | K50: 291.05 | L50: 282 | M50: =L50-K50 -> -9.05 | N50: =K50*J50 -> 18918.25 | O50: =M50/K50 -> -0.031094314 | P50: =O50+P49 -> 1.4529159 | Q50: =M50+Q49 -> 121.507 | R50: =E50-D50 -> 0.0011111111 | S50: 40 | T50: 41.596419 | U50: -588.25 | V50: -669.84642 | W50: =T50+S50 -> 81.596419
A51: 46051 | B51: W4 | C51: =TEXTJOIN( " | ", TRUE, TEXT(A51,"ddd dd - mmm"), TEXT(D51,"hh:mm"), G51, TEXT(I51,"0") ) -> Thu 29 - Jan | 11:52 | Short | 7 | D51: 0.49459491 | E51: 0.50231481 | F51: NIFTY 03 FEB 25400 PUT | G51: Short | H51: Manual | I51: 7 | J51: 65 | K51: 257.1 | L51: 247.1 | M51: =L51-K51 -> -10 | N51: =K51*J51 -> 16711.5 | O51: =M51/K51 -> -0.038895371 | P51: =O51+P50 -> 1.4140205 | Q51: =M51+Q50 -> 111.507 | R51: =E51-D51 -> 0.0077199074 | S51: 40 | T51: 37.399938 | U51: -650 | V51: -727.39994 | W51: =T51+S51 -> 77.399938
A52: 46051 | B52: W4 | C52: =TEXTJOIN( " | ", TRUE, TEXT(A52,"ddd dd - mmm"), TEXT(D52,"hh:mm"), G52, TEXT(I52,"0") ) -> Thu 29 - Jan | 12:12 | Long | 8 | D52: 0.50836806 | E52: 0.52005787 | F52: NIFTY 03 FEB 25300 CALL | G52: Long | H52: Conti | I52: 8 | J52: 130 | K52: 186.6 | L52: 186.5 | M52: =L52-K52 -> -0.1 | N52: =K52*J52 -> 24258 | O52: =M52/K52 -> -0.00053590568 | P52: =O52+P51 -> 1.4134846 | Q52: =M52+Q51 -> 111.407 | R52: =E52-D52 -> 0.011689815 | S52: 40 | T52: 52.352642 | U52: -13 | V52: -105.35264 | W52: =T52+S52 -> 92.352642
A53: 46051 | B53: W4 | C53: =TEXTJOIN( " | ", TRUE, TEXT(A53,"ddd dd - mmm"), TEXT(D53,"hh:mm"), G53, TEXT(I53,"0") ) -> Thu 29 - Jan | 12:51 | Long | 9 | D53: 0.53545139 | E53: 0.54751157 | F53: NIFTY 03 FEB 25400 CALL | G53: Long | H53: Reversal | I53: 9 | J53: 65 | K53: 161.85 | L53: 186.3 | M53: =L53-K53 -> 24.45 | N53: =K53*J53 -> 10520.25 | O53: =M53/K53 -> 0.1510658 | P53: =O53+P52 -> 1.5645504 | Q53: =M53+Q52 -> 135.857 | R53: =E53-D53 -> 0.012060185 | S53: 40 | T53: 29.036015 | U53: 1589.25 | V53: 1520.214 | W53: =T53+S53 -> 69.036015
A54: 46052 | B54: W4 | C54: =TEXTJOIN( " | ", TRUE, TEXT(A54,"ddd dd - mmm"), TEXT(D54,"hh:mm"), G54, TEXT(I54,"0") ) -> Fri 30 - Jan | 11:09 | Short | 1 | D54: 0.46461806 | E54: 0.47068287 | F54: NIFTY 03 FEB 25300 PUT | G54: Short | H54: Conti | I54: 1 | J54: 65 | K54: 204.6 | L54: 220.5 | M54: =L54-K54 -> 15.9 | N54: =K54*J54 -> 13299 | O54: =M54/K54 -> 0.07771261 | P54: =O54+P53 -> 1.642263 | Q54: =M54+Q53 -> 151.757 | R54: =E54-D54 -> 0.0060648148 | S54: 40 | T54: 33.424876 | U54: 1033.5 | V54: 960.07512 | W54: =T54+S54 -> 73.424876
A55: 46052 | B55: W4 | C55: =TEXTJOIN( " | ", TRUE, TEXT(A55,"ddd dd - mmm"), TEXT(D55,"hh:mm"), G55, TEXT(I55,"0") ) -> Fri 30 - Jan | 11:09 | Short | 1 | D55: 0.46461806 | E55: 0.47744213 | F55: NIFTY 03 FEB 25300 PUT | G55: Short | H55: Conti | I55: 1 | J55: 65 | K55: 204.6 | L55: 201.1 | M55: =L55-K55 -> -3.5 | N55: =K55*J55 -> 13299 | O55: =M55/K55 -> -0.017106549 | P55: =O55+P54 -> 1.6251565 | Q55: =M55+Q54 -> 148.257 | R55: =E55-D55 -> 0.012824074 | S55: 40 | T55: 31.642636 | U55: -227.5 | V55: -299.14264 | W55: =T55+S55 -> 71.642636
A56: 46052 | B56: W4 | C56: =TEXTJOIN( " | ", TRUE, TEXT(A56,"ddd dd - mmm"), TEXT(D56,"hh:mm"), G56, TEXT(I56,"0") ) -> Fri 30 - Jan | 11:49 | Short | 2 | D56: 0.49247685 | E56: 0.49384259 | F56: NIFTY 03 FEB 25450 PUT | G56: Short | H56: Manual | I56: 2 | J56: 65 | K56: 307.3 | L56: 299.05 | M56: =L56-K56 -> -8.25 | N56: =K56*J56 -> 19974.5 | O56: =M56/K56 -> -0.02684673 | P56: =O56+P55 -> 1.5983097 | Q56: =M56+Q55 -> 140.007 | R56: =E56-D56 -> 0.0013657407 | S56: 40 | T56: 43.636765 | U56: -536.25 | V56: -619.88677 | W56: =T56+S56 -> 83.636765
A57: 46052 | B57: W4 | C57: =TEXTJOIN( " | ", TRUE, TEXT(A57,"ddd dd - mmm"), TEXT(D57,"hh:mm"), G57, TEXT(I57,"0") ) -> Fri 30 - Jan | 13:36 | Long | 3 | D57: 0.56668981 | E57: 0.58409722 | F57: NIFTY 03 FEB 25350 CALL | G57: Long | H57: Reversal | I57: 3 | J57: 65 | K57: 166.5 | L57: 202.1 | M57: =L57-K57 -> 35.6 | N57: =K57*J57 -> 10822.5 | O57: =M57/K57 -> 0.21381381 | P57: =O57+P56 -> 1.8121235 | Q57: =M57+Q56 -> 175.607 | R57: =E57-D57 -> 0.017407407 | S57: 40 | T57: 30.623165 | U57: 2314 | V57: 2243.3768 | W57: =T57+S57 -> 70.623165
A58: 46055 | B58: W5 | C58: =TEXTJOIN( " | ", TRUE, TEXT(A58,"ddd dd - mmm"), TEXT(D58,"hh:mm"), G58, TEXT(I58,"0") ) -> Mon 02 - Feb | 14:00 | 1 | D58: 0.58342593 | E58: 0.59796296 | F58: NIFTY 03 FEB 24850 PUT | I58: 1 | J58: 65 | K58: 68.2 | L58: 66.4 | M58: =L58-K58 -> -1.8 | N58: =K58*J58 -> 4433 | O58: =M58/K58 -> -0.026392962 | P58: =O58+P57 -> 1.7857306 | Q58: =M58+Q57 -> 173.807 | R58: =E58-D58 -> 0.014537037 | S58: 40 | T58: 15.289362 | U58: -117 | V58: -172.28936 | W58: =T58+S58 -> 55.289362
A59: 46055 | B59: W5 | C59: =TEXTJOIN( " | ", TRUE, TEXT(A59,"ddd dd - mmm"), TEXT(D59,"hh:mm"), G59, TEXT(I59,"0") ) -> Mon 02 - Feb | 14:00 | 1 | D59: 0.58342593 | E59: 0.61625 | F59: NIFTY 03 FEB 24850 PUT | I59: 1 | J59: 65 | K59: 68.2 | L59: 59.55 | M59: =L59-K59 -> -8.65 | N59: =K59*J59 -> 4433 | O59: =M59/K59 -> -0.12683284 | P59: =O59+P58 -> 1.6588977 | Q59: =M59+Q58 -> 165.157 | R59: =E59-D59 -> 0.032824074 | S59: 40 | T59: 14.660066 | U59: -562.25 | V59: -616.91007 | W59: =T59+S59 -> 54.660066
A60: 46056 | B60: W5 | C60: =TEXTJOIN( " | ", TRUE, TEXT(A60,"ddd dd - mmm"), TEXT(D60,"hh:mm"), G60, TEXT(I60,"0") ) -> Tue 03 - Feb | 10:50 | 1 | D60: 0.45168981 | E60: 0.45424769 | F60: NIFTY 10 FEB 25800 PUT | I60: 1 | J60: 65 | K60: 237.2 | L60: 236.1 | M60: =L60-K60 -> -1.1 | N60: =K60*J60 -> 15418 | O60: =M60/K60 -> -0.0046374368 | P60: =O60+P59 -> 1.6542603 | Q60: =M60+Q59 -> 164.057 | R60: =E60-D60 -> 0.0025578704 | S60: 40 | T60: 35.808926 | U60: -71.5 | V60: -147.30893 | W60: =T60+S60 -> 75.808926
A61: 46056 | B61: W5 | C61: =TEXTJOIN( " | ", TRUE, TEXT(A61,"ddd dd - mmm"), TEXT(D61,"hh:mm"), G61, TEXT(I61,"0") ) -> Tue 03 - Feb | 11:10 | 2 | D61: 0.46540509 | E61: 0.4675463 | F61: NIFTY 10 FEB 25800 PUT | I61: 2 | J61: 65 | K61: 225 | L61: 220.95 | M61: =L61-K61 -> -4.05 | N61: =K61*J61 -> 14625 | O61: =M61/K61 -> -0.018 | P61: =O61+P60 -> 1.6362603 | Q61: =M61+Q60 -> 160.007 | R61: =E61-D61 -> 0.0021412037 | S61: 40 | T61: 34.061264 | U61: -263.25 | V61: -337.31126 | W61: =T61+S61 -> 74.061264
A62: 46056 | B62: W5 | C62: =TEXTJOIN( " | ", TRUE, TEXT(A62,"ddd dd - mmm"), TEXT(D62,"hh:mm"), G62, TEXT(I62,"0") ) -> Tue 03 - Feb | 11:27 | 3 | D62: 0.47710648 | E62: 0.48171296 | F62: NIFTY 10 FEB 25800 CALL | I62: 3 | J62: 65 | K62: 228.2 | L62: 251.85 | M62: =L62-K62 -> 23.65 | N62: =K62*J62 -> 14833 | O62: =M62/K62 -> 0.10363716 | P62: =O62+P61 -> 1.7398975 | Q62: =M62+Q61 -> 183.657 | R62: =E62-D62 -> 0.0046064815 | S62: 40 | T62: 36.993326 | U62: 1537.25 | V62: 1460.2567 | W62: =T62+S62 -> 76.993326
A63: 46056 | B63: W5 | C63: =TEXTJOIN( " | ", TRUE, TEXT(A63,"ddd dd - mmm"), TEXT(D63,"hh:mm"), G63, TEXT(I63,"0") ) -> Tue 03 - Feb | 11:27 | 3 | D63: 0.47710648 | E63: 0.48493056 | F63: NIFTY 10 FEB 25800 CALL | I63: 3 | J63: 65 | K63: 228.2 | L63: 242.15 | M63: =L63-K63 -> 13.95 | N63: =K63*J63 -> 14833 | O63: =M63/K63 -> 0.061130587 | P63: =O63+P62 -> 1.8010281 | Q63: =M63+Q62 -> 197.607 | R63: =E63-D63 -> 0.0078240741 | S63: 40 | T63: 36.102207 | U63: 906.75 | V63: 830.64779 | W63: =T63+S63 -> 76.102207
A64: 46057 | B64: W5 | C64: =TEXTJOIN( " | ", TRUE, TEXT(A64,"ddd dd - mmm"), TEXT(D64,"hh:mm"), G64, TEXT(I64,"0") ) -> Wed 04 - Feb | 10:15 | 1 | D64: 0.42712963 | E64: 0.44248843 | F64: NIFTY 10 FEB 25700 PUT | I64: 1 | J64: 65 | K64: 131.15 | L64: 152.1 | M64: =L64-K64 -> 20.95 | N64: =K64*J64 -> 8524.75 | O64: =M64/K64 -> 0.15974075 | P64: =O64+P63 -> 1.9607688 | Q64: =M64+Q63 -> 218.557 | R64: =E64-D64 -> 0.015358796 | S64: 40 | T64: 24.99864 | U64: 1361.75 | V64: 1296.7514 | W64: =T64+S64 -> 64.99864
...

Sheet DATA
D1: 45853 | E1: 45854 | F1: 45855 | G1: 45856 | H1: 45859 | I1: 45860 | J1: 45861 | K1: 45862 | L1: 45863 | M1: 45866 | N1: 45867 | O1: 45868 | P1: 45869 | Q1: 45870 | R1: 45873 | S1: 45874 | T1: 45875 | U1: 45876 | V1: 45877 | W1: 45880 | X1: 45881 | Y1: 45882 | Z1: 45883 | AA1: 45887 | AB1: 45888 | AC1: 45889 | AD1: 45890 | AE1: 45891 | AF1: 45894 | AG1: 45895 | AH1: 45897 | AI1: 45898 | AJ1: 45901 | AK1: 45902 | AL1: 45903 | AM1: 45904 | AN1: 45905 | AO1: 45908 | AP1: 45909 | AQ1: 45910 | AR1: 45911 | AS1: 45912 | AT1: 45915 | AU1: 45916 | AV1: 45917 | AW1: 45918 | AX1: 45919 | AY1: 45922 | AZ1: 45923 | BA1: 45924 | BB1: 45925 | BC1: 45926 | BD1: 45929 | BE1: 45930 | BF1: 45931 | BG1: 45933 | BH1: 45936 | BI1: 45937 | BJ1: 45938 | BK1: 45939 | BL1: 45940 | BM1: 45943 | BN1: 45944 | BO1: 45945 | BP1: 45946 | BQ1: 45947 | BR1: 45950 | BS1: 45953 | BT1: 45954 | BU1: 45957 | BV1: 45958 | BW1: 45959 | BX1: 45960 | BY1: 45961 | BZ1: 45964 | CA1: 45965 | CB1: 45967 | CC1: 45968 | CD1: 45971 | CE1: 45972 | CF1: 45973 | CG1: 45974 | CH1: 45975 | CI1: 45978 | CJ1: 45979 | CK1: 45980 | CL1: 45981 | CM1: 45982 | CN1: 45985 | CO1: 45986 | CP1: 45987 | CQ1: 45988 | CR1: 45989 | CS1: 45992 | CT1: 45993 | CU1: 45994 | CV1: 45995 | CW1: 45996 | CX1: 45999 | CY1: 46000 | CZ1: 46001 | DA1: 46002 | DB1: 46003 | DC1: 46006 | DD1: 46007 | DE1: 46008 | DF1: 46009 | DG1: 46010 | DH1: 46013 | DI1: 46014 | DJ1: 46015 | DK1: 46017 | DL1: 46020 | DM1: 46021 | DN1: 46022 | DO1: 46023 | DP1: 46024 | DQ1: 46027 | DR1: 46028 | DS1: 46029 | DT1: 46030 | DU1: 46031 | DV1: 46034 | DW1: 46035 | DX1: 46036 | DY1: 46038 | DZ1: 46041 | EA1: 46042 | EB1: 46043 | EC1: 46044 | ED1: 46045 | EE1: 46049 | EF1: 46050 | EG1: 46051 | EH1: 46052 | EI1: 46054 | EJ1: 46054 | EK1: 46055 | EL1: 46056 | EM1: 46057 | EN1: 46058 | EO1: 46059 | EP1: 46062 | EQ1: 46063 | ER1: 46064 | ES1: 46065 | ET1: 46066 | EU1: 46069 | EV1: 46070 | EW1: 46071 | EX1: 46072 | EY1: 46073 | EZ1: 46076 | FA1: 46077 | FB1: 46078 | FC1: 46079
A2: P&L | Q2: -1023.75 | R2: 2635.5 | S2: -1974 | T2: -1790.25 | U2: -38.5 | V2: -792.75 | W2: -2184 | X2: 450.5 | Y2: 25.25 | Z2: -418.25 | AA2: 1384.25 | AB2: -1768 | AC2: 1606.5 | AD2: 392 | AE2: -2826.25 | AF2: 1363.25 | AG2: 208.25 | AH2: 1940.75 | AI2: 716.5 | AJ2: -810 | AK2: 1347.5 | AL2: 768.75 | AM2: 1200 | AN2: -9614.75 | AO2: 2876.25 | AP2: 958 | AQ2: -1200 | AR2: -810 | AS2: -3300 | AT2: -1064 | AU2: 375 | AV2: -3183.75 | AW2: 321 | AX2: -1930.25 | AY2: 1088.5 | AZ2: -2640.75 | BA2: 772.5 | BB2: -25.5 | BC2: -2539.75 | BD2: 1041.25 | BE2: 705.25 | BF2: 1146.25 | BG2: -3927 | BH2: 908 | BI2: 3112 | BJ2: -2219 | BK2: -2000 | BL2: 3000 | BM2: -2227 | DA2: NO TRADE
A3: Trade | Q3: 6 | R3: 3 | S3: 5 | T3: 2 | U3: 6 | V3: 3 | W3: 2 | X3: 3 | Y3: 8 | Z3: 7 | AA3: 2 | AB3: 9 | AC3: 4 | AD3: 4 | AE3: 9 | AF3: 1 | AG3: 2 | AH3: 2 | AI3: 2 | AJ3: 6 | AK3: 1 | AL3: 2 | AM3: 3 | AN3: 5 | AO3: 4 | AP3: 10 | AQ3: 4 | AR3: 3 | AS3: 7 | AT3: 2 | AU3: 1 | AV3: 5 | AW3: 7 | AX3: 13 | AY3: 2 | AZ3: 11 | BA3: 1 | BB3: 9 | BC3: 9 | BD3: 1 | BE3: 1 | BF3: 1 | BG3: 5 | BH3: 1
A5: START | AJ5: startDate = input.time(timestamp("2025-09-01 03:45"), title="Start Date", group="Date Range") | AK5: startDate = input.time(timestamp("2025-09-02 03:45"), title="Start Date", group="Date Range") | AL5: startDate = input.time(timestamp("2025-09-03 03:45"), title="Start Date", group="Date Range") | AM5: startDate = input.time(timestamp("2025-09-04 03:45"), title="Start Date", group="Date Range") | AN5: startDate = input.time(timestamp("2025-09-05 03:45"), title="Start Date", group="Date Range") | AO5: startDate = input.time(timestamp("2025-09-08 03:45"), title="Start Date", group="Date Range") | AP5: startDate = input.time(timestamp("2025-09-09 03:45"), title="Start Date", group="Date Range") | AQ5: startDate = input.time(timestamp("2025-09-10 03:45"), title="Start Date", group="Date Range") | AR5: startDate = input.time(timestamp("2025-09-11 03:45"), title="Start Date", group="Date Range") | AS5: startDate = input.time(timestamp("2025-09-12 03:45"), title="Start Date", group="Date Range") | AT5: startDate = input.time(timestamp("2025-09-15 03:45"), title="Start Date", group="Date Range") | AU5: startDate = input.time(timestamp("2025-09-16 03:45"), title="Start Date", group="Date Range") | AV5: startDate = input.time(timestamp("2025-09-17 03:45"), title="Start Date", group="Date Range") | AW5: startDate = input.time(timestamp("2025-09-18 03:45"), title="Start Date", group="Date Range") | AX5: startDate = input.time(timestamp("2025-09-19 03:45"), title="Start Date", group="Date Range") | AY5: startDate = input.time(timestamp("2025-09-22 03:45"), title="Start Date", group="Date Range") | AZ5: startDate = input.time(timestamp("2025-09-23 03:45"), title="Start Date", group="Date Range") | BA5: startDate = input.time(timestamp("2025-09-24 03:45"), title="Start Date", group="Date Range") | BB5: startDate = input.time(timestamp("2025-09-25 03:45"), title="Start Date", group="Date Range") | BC5: startDate = input.time(timestamp("2025-09-26 03:45"), title="Start Date", group="Date Range") | BD5: startDate = input.time(timestamp("2025-09-29 03:45"), title="Start Date", group="Date Range") | BE5: startDate = input.time(timestamp("2025-09-30 03:45"), title="Start Date", group="Date Range") | BF5: startDate = input.time(timestamp("2025-10-01 03:45"), title="Start Date", group="Date Range") | BG5: startDate = input.time(timestamp("2025-10-03 03:45"), title="Start Date", group="Date Range") | BH5: startDate = input.time(timestamp("2025-10-06 03:45"), title="Start Date", group="Date Range") | BI5: startDate = input.time(timestamp("2025-10-07 03:45"), title="Start Date", group="Date Range") | BJ5: startDate = input.time(timestamp("2025-10-08 03:45"), title="Start Date", group="Date Range") | BK5: startDate = input.time(timestamp("2025-10-09 03:45"), title="Start Date", group="Date Range") | BL5: startDate = input.time(timestamp("2025-10-10 03:45"), title="Start Date", group="Date Range") | BM5: startDate = input.time(timestamp("2025-10-13 03:45"), title="Start Date", group="Date Range") | BN5: startDate = input.time(timestamp("2025-10-14 03:45"), title="Start Date", group="Date Range") | BO5: startDate = input.time(timestamp("2025-10-15 03:45"), title="Start Date", group="Date Range") | BP5: startDate = input.time(timestamp("2025-10-16 03:45"), title="Start Date", group="Date Range") | BQ5: startDate = input.time(timestamp("2025-10-17 03:45"), title="Start Date", group="Date Range") | BR5: startDate = input.time(timestamp("2025-10-20 03:45"), title="Start Date", group="Date Range") | BS5: startDate = input.time(timestamp("2025-10-23 03:45"), title="Start Date", group="Date Range") | BT5: startDate = input.time(timestamp("2025-10-24 03:45"), title="Start Date", group="Date Range") | BU5: startDate = input.time(timestamp("2025-10-27 03:45"), title="Start Date", group="Date Range") | BV5: startDate = input.time(timestamp("2025-10-28 03:45"), title="Start Date", group="Date Range") | BW5: startDate = input.time(timestamp("2025-10-29 03:45"), title="Start Date", group="Date Range") | BX5: startDate = input.time(timestamp("2025-10-30 03:45"), title="Start Date", group="Date Range") | BY5: startDate = input.time(timestamp("2025-10-31 03:45"), title="Start Date", group="Date Range") | BZ5: startDate = input.time(timestamp("2025-11-03 03:45"), title="Start Date", group="Date Range") | CA5: startDate = input.time(timestamp("2025-11-04 03:45"), title="Start Date", group="Date Range") | CB5: startDate = input.time(timestamp("2025-11-06 03:45"), title="Start Date", group="Date Range") | CC5: startDate = input.time(timestamp("2025-11-07 03:45"), title="Start Date", group="Date Range") | CD5: startDate = input.time(timestamp("2025-11-10 03:45"), title="Start Date", group="Date Range") | CE5: startDate = input.time(timestamp("2025-11-11 03:45"), title="Start Date", group="Date Range") | CF5: startDate = input.time(timestamp("2025-11-12 03:45"), title="Start Date", group="Date Range") | CG5: startDate = input.time(timestamp("2025-11-13 03:45"), title="Start Date", group="Date Range") | CH5: startDate = input.time(timestamp("2025-11-14 03:45"), title="Start Date", group="Date Range") | CI5: startDate = input.time(timestamp("2025-11-17 03:45"), title="Start Date", group="Date Range") | CJ5: startDate = input.time(timestamp("2025-11-18 03:45"), title="Start Date", group="Date Range") | CK5: startDate = input.time(timestamp("2025-11-19 03:45"), title="Start Date", group="Date Range") | CL5: startDate = input.time(timestamp("2025-11-20 03:45"), title="Start Date", group="Date Range") | CM5: startDate = input.time(timestamp("2025-11-21 03:45"), title="Start Date", group="Date Range") | CN5: startDate = input.time(timestamp("2025-11-24 03:45"), title="Start Date", group="Date Range") | CO5: startDate = input.time(timestamp("2025-11-25 03:45"), title="Start Date", group="Date Range") | CP5: startDate = input.time(timestamp("2025-11-28603:45"), title="Start Date", group="Date Range") | CQ5: startDate = input.time(timestamp("2025-11-27 03:45"), title="Start Date", group="Date Range") | CR5: startDate = input.time(timestamp("2025-11-28 03:45"), title="Start Date", group="Date Range") | CS5: startDate = input.time(timestamp("2025-12-01 03:45"), title="Start Date", group="Date Range") | CT5: startDate = input.time(timestamp("2025-12-02 03:45"), title="Start Date", group="Date Range") | CU5: startDate = input.time(timestamp("2025-12-03 03:45"), title="Start Date", group="Date Range") | CV5: startDate = input.time(timestamp("2025-12-04 03:45"), title="Start Date", group="Date Range") | CW5: startDate = input.time(timestamp("2025-12-05 03:45"), title="Start Date", group="Date Range") | CX5: startDate = input.time(timestamp("2025-12-08 03:45"), title="Start Date", group="Date Range") | CY5: startDate = input.time(timestamp("2025-12-09 03:45"), title="Start Date", group="Date Range") | CZ5: startDate = input.time(timestamp("2025-12-10 03:45"), title="Start Date", group="Date Range") | DA5: startDate = input.time(timestamp("2025-12-11 03:45"), title="Start Date", group="Date Range") | DB5: startDate = input.time(timestamp("2025-12-12 03:45"), title="Start Date", group="Date Range") | DC5: startDate = input.time(timestamp("2025-12-15 03:45"), title="Start Date", group="Date Range") | DD5: startDate = input.time(timestamp("2025-12-16 03:45"), title="Start Date", group="Date Range") | DE5: startDate = input.time(timestamp("2025-12-17 03:45"), title="Start Date", group="Date Range") | DF5: startDate = input.time(timestamp("2025-12-18 03:45"), title="Start Date", group="Date Range") | DG5: startDate = input.time(timestamp("2025-12-19 03:45"), title="Start Date", group="Date Range") | DH5: startDate = input.time(timestamp("2025-12-22 03:45"), title="Start Date", group="Date Range") | DI5: startDate = input.time(timestamp("2025-12-23 03:45"), title="Start Date", group="Date Range") | DJ5: startDate = input.time(timestamp("2025-12-24 03:45"), title="Start Date", group="Date Range") | DK5: tartDate = input.time(timestamp("2025-12-26 03:45"), title="Start Date", group="Date Range") | DL5: startDate = input.time(timestamp("2025-12-29 03:45"), title="Start Date", group="Date Range") | DM5: startDate = input.time(timestamp("2025-12-31 03:45"), title="Start Date", group="Date Range") | DN5: startDate = input.time(timestamp("2025-12-31 03:45"), title="Start Date", group="Date Range") | DO5: startDate = input.time(timestamp("2026-01-01 03:45"), title="Start Date", group="Date Range") | DP5: startDate = input.time(timestamp("2026-01-02 03:45"), title="Start Date", group="Date Range") | DQ5: startDate = input.time(timestamp("2026-01-05 03:45"), title="Start Date", group="Date Range") | DS5: startDate = input.time(timestamp("2026-01-08 03:45"), title="Start Date", group="Date Range") | DT5: startDate = input.time(timestamp("2026-01-08 03:45"), title="Start Date", group="Date Range") | DU5: startDate = input.time(timestamp("2026-01-09 03:45"), title="Start Date", group="Date Range") | DV5: startDate = input.time(timestamp("2026-01-12 03:45"), title="Start Date", group="Date Range") | DW5: tartDate = input.time(timestamp("2026-01-13 03:45"), title="Start Date", group="Date Range") | DZ5: tartDate = input.time(timestamp("2026-01-19 03:45"), title="Start Date", group="Date Range") | EA5: startDate = input.time(timestamp("2026-01-20 03:45"), title="Start Date", group="Date Range") | EE5: startDate = input.time(timestamp("2026-01-28 03:45"), title="Start Date", group="Date Range") | EF5: startDate = input.time(timestamp("2026-01-29 03:45"), title="Start Date", group="Date Range") | EG5: startDate = input.time(timestamp("2026-01-30 03:45"), title="Start Date", group="Date Range") | EH5: startDate = input.time(timestamp("2026-01-30 03:45"), title="Start Date", group="Date Range") | EI5: startDate = input.time(timestamp("2026-02-02 03:45"), title="Start Date", group="Date Range") | EJ5: startDate = input.time(timestamp("2026-02-03 03:45"), title="Start Date", group="Date Range") | EL5: startDate = input.time(timestamp("2026-02-04 03:45"), title="Start Date", group="Date Range") | EM5: startDate = input.time(timestamp("2026-02-05 03:45"), title="Start Date", group="Date Range") | EP5: startDate = input.time(timestamp("2026-02-09 03:45"), title="Start Date", group="Date Range") | EQ5: startDate = input.time(timestamp("2026-02-10 03:45"), title="Start Date", group="Date Range") | ER5: startDate = input.time(timestamp("2026-02-11 03:45"), title="Start Date", group="Date Range") | EU5: startDate = input.time(timestamp("2026-02-16 03:45"), title="Start Date", group="Date Range") | EV5: startDate = input.time(timestamp("2026-02-17 03:45"), title="Start Date", group="Date Range") | EW5: startDate = input.time(timestamp("2026-02-18 03:45"), title="Start Date", group="Date Range") | EX5: startDate = input.time(timestamp("2026-02-19 03:45"), title="Start Date", group="Date Range") | EY5: startDate = input.time(timestamp("2026-02-20 03:45"), title="Start Date", group="Date Range") | EZ5: startDate = input.time(timestamp("2026-02-23 03:45"), title="Start Date", group="Date Range") | FA5: startDate = input.time(timestamp("2026-02-24 03:45"), title="Start Date", group="Date Range") | FB5: startDate = input.time(timestamp("2026-02-25 03:45"), title="Start Date", group="Date Range") | FC5: startDate = input.time(timestamp("2026-02-26 03:45"), title="Start Date", group="Date Range")
A6: END | AJ6: endDate = input.time(timestamp("2025-09-01 10:00"), title="End Date", group="Date Range")//10:00 | AK6: endDate = input.time(timestamp("2025-09-02 10:00"), title="End Date", group="Date Range")//10:00 | AL6: endDate = input.time(timestamp("2025-09-03 10:00"), title="End Date", group="Date Range")//10:00 | AM6: endDate = input.time(timestamp("2025-09-04 10:00"), title="End Date", group="Date Range")//10:00 | AN6: endDate = input.time(timestamp("2025-09-05 10:00"), title="End Date", group="Date Range")//10:00 | AO6: endDate = input.time(timestamp("2025-09-08 10:00"), title="End Date", group="Date Range")//10:00 | AP6: endDate = input.time(timestamp("2025-09-09 10:00"), title="End Date", group="Date Range")//10:00 | AQ6: endDate = input.time(timestamp("2025-09-10 10:00"), title="End Date", group="Date Range")//10:00 | AR6: endDate = input.time(timestamp("2025-09-11 10:00"), title="End Date", group="Date Range")//10:00 | AS6: endDate = input.time(timestamp("2025-09-12 10:00"), title="End Date", group="Date Range")//10:00 | AT6: endDate = input.time(timestamp("2025-09-15 10:00"), title="End Date", group="Date Range")//10:00 | AU6: endDate = input.time(timestamp("2025-09-16 10:00"), title="End Date", group="Date Range")//10:00 | AV6: endDate = input.time(timestamp("2025-09-17 10:00"), title="End Date", group="Date Range")//10:00 | AW6: endDate = input.time(timestamp("2025-09-18 10:00"), title="End Date", group="Date Range")//10:00 | AX6: endDate = input.time(timestamp("2025-09-19 10:00"), title="End Date", group="Date Range")//10:00 | AY6: endDate = input.time(timestamp("2025-09-22 10:00"), title="End Date", group="Date Range")//10:00 | AZ6: endDate = input.time(timestamp("2025-09-23 10:00"), title="End Date", group="Date Range")//10:00 | BA6: endDate = input.time(timestamp("2025-09-24 10:00"), title="End Date", group="Date Range")//10:00 | BB6: endDate = input.time(timestamp("2025-09-25 10:00"), title="End Date", group="Date Range")//10:00 | BC6: endDate = input.time(timestamp("2025-09-26 10:00"), title="End Date", group="Date Range")//10:00 | BD6: endDate = input.time(timestamp("2025-09-29 10:00"), title="End Date", group="Date Range")//10:00 | BE6: endDate = input.time(timestamp("2025-09-30 10:00"), title="End Date", group="Date Range")//10:00 | BF6: endDate = input.time(timestamp("2025-10-01 10:00"), title="End Date", group="Date Range")//10:00 | BG6: endDate = input.time(timestamp("2025-10-03 10:00"), title="End Date", group="Date Range")//10:00 | BH6: endDate = input.time(timestamp("2025-10-06 10:00"), title="End Date", group="Date Range")//10:00 | BI6: endDate = input.time(timestamp("2025-10-07 10:00"), title="End Date", group="Date Range")//10:00 | BJ6: endDate = input.time(timestamp("2025-10-08 10:00"), title="End Date", group="Date Range")//10:00 | BK6: endDate = input.time(timestamp("2025-10-09 10:00"), title="End Date", group="Date Range")//10:00 | BL6: endDate = input.time(timestamp("2025-10-10 10:00"), title="End Date", group="Date Range")//10:00 | BM6: endDate = input.time(timestamp("2025-10-13 10:00"), title="End Date", group="Date Range")//10:00 | BN6: endDate = input.time(timestamp("2025-10-14 10:00"), title="End Date", group="Date Range")//10:00 | BO6: endDate = input.time(timestamp("2025-10-15 10:00"), title="End Date", group="Date Range")//10:00 | BP6: endDate = input.time(timestamp("2025-10-16 10:00"), title="End Date", group="Date Range")//10:00 | BQ6: endDate = input.time(timestamp("2025-10-17 10:00"), title="End Date", group="Date Range")//10:00 | BR6: endDate = input.time(timestamp("2025-10-20 10:00"), title="End Date", group="Date Range")//10:00 | BS6: endDate = input.time(timestamp("2025-10-23 10:00"), title="End Date", group="Date Range")//10:00 | BT6: endDate = input.time(timestamp("2025-10-24 10:00"), title="End Date", group="Date Range")//10:00 | BU6: endDate = input.time(timestamp("2025-10-27 10:00"), title="End Date", group="Date Range")//10:00 | BV6: endDate = input.time(timestamp("2025-10-28 10:00"), title="End Date", group="Date Range")//10:00 | BW6: endDate = input.time(timestamp("2025-10-29 10:00"), title="End Date", group="Date Range")//10:00 | BX6: endDate = input.time(timestamp("2025-10-30 10:00"), title="End Date", group="Date Range")//10:00 | BY6: endDate = input.time(timestamp("2025-10-31 10:00"), title="End Date", group="Date Range")//10:00 | BZ6: endDate = input.time(timestamp("2025-11-03 10:00"), title="End Date", group="Date Range")//10:00 | CA6: endDate = input.time(timestamp("2025-11-04 10:00"), title="End Date", group="Date Range")//10:00 | CB6: endDate = input.time(timestamp("2025-11-06 10:00"), title="End Date", group="Date Range")//10:00 | CC6: endDate = input.time(timestamp("2025-11-07 10:00"), title="End Date", group="Date Range")//10:00 | CD6: endDate = input.time(timestamp("2025-11-10 10:00"), title="End Date", group="Date Range")//10:00 | CE6: endDate = input.time(timestamp("2025-11-11 10:00"), title="End Date", group="Date Range")//10:00 | CF6: endDate = input.time(timestamp("2025-11-12 10:00"), title="End Date", group="Date Range")//10:00 | CG6: endDate = input.time(timestamp("2025-11-13 10:00"), title="End Date", group="Date Range")//10:00 | CH6: endDate = input.time(timestamp("2025-11-14 10:00"), title="End Date", group="Date Range")//10:00 | CI6: endDate = input.time(timestamp("2025-11-17 10:00"), title="End Date", group="Date Range")//10:00 | CJ6: endDate = input.time(timestamp("2025-11-18 10:00"), title="End Date", group="Date Range")//10:00 | CK6: endDate = input.time(timestamp("2025-11-19 10:00"), title="End Date", group="Date Range")//10:00 | CL6: endDate = input.time(timestamp("2025-11-20 10:00"), title="End Date", group="Date Range")//10:00 | CM6: endDate = input.time(timestamp("2025-11-21 10:00"), title="End Date", group="Date Range")//10:00 | CN6: endDate = input.time(timestamp("2025-11-24 10:00"), title="End Date", group="Date Range")//10:00 | CO6: endDate = input.time(timestamp("2025-11-25 10:00"), title="End Date", group="Date Range")//10:00 | CP6: endDate = input.time(timestamp("2025-11-26 10:00"), title="End Date", group="Date Range")//10:00 | CQ6: endDate = input.time(timestamp("2025-11-27 10:00"), title="End Date", group="Date Range")//10:00 | CR6: endDate = input.time(timestamp("2025-11-28 10:00"), title="End Date", group="Date Range")//10:00 | CS6: endDate = input.time(timestamp("2025-12-01 10:00"), title="End Date", group="Date Range")//10:00 | CT6: endDate = input.time(timestamp("2025-12-02 10:00"), title="End Date", group="Date Range")//10:00 | CU6: endDate = input.time(timestamp("2025-12-03 10:00"), title="End Date", group="Date Range")//10:00 | CV6: endDate = input.time(timestamp("2025-12-04 10:00"), title="End Date", group="Date Range")//10:00 | CW6: endDate = input.time(timestamp("2025-12-05 10:00"), title="End Date", group="Date Range")//10:00 | CX6: endDate = input.time(timestamp("2025-12-08 10:00"), title="End Date", group="Date Range")//10:00 | CY6: endDate = input.time(timestamp("2025-12-09 10:00"), title="End Date", group="Date Range")//10:00 | CZ6: endDate = input.time(timestamp("2025-12-10 10:00"), title="End Date", group="Date Range")//10:00 | DA6: endDate = input.time(timestamp("2025-12-11 10:00"), title="End Date", group="Date Range")//10:00 | DB6: endDate = input.time(timestamp("2025-12-12 10:00"), title="End Date", group="Date Range")//10:00 | DC6: endDate = input.time(timestamp("2025-12-15 10:00"), title="End Date", group="Date Range")//10:00 | DD6: endDate = input.time(timestamp("2025-12-16 10:00"), title="End Date", group="Date Range")//10:00 | DE6: endDate = input.time(timestamp("2025-12-17 10:00"), title="End Date", group="Date Range")//10:00 | DF6: endDate = input.time(timestamp("2025-12-18 10:00"), title="End Date", group="Date Range")//10:00 | DG6: endDate = input.time(timestamp("2025-12-19 10:00"), title="End Date", group="Date Range")//10:00 | DH6: endDate = input.time(timestamp("2025-12-22 10:00"), title="End Date", group="Date Range")//10:00 | DI6: endDate = input.time(timestamp("2025-12-23 10:00"), title="End Date", group="Date Range")//10:00 | DJ6: endDate = input.time(timestamp("2025-12-24 10:00"), title="End Date", group="Date Range")//10:00 | DK6: endDate = input.time(timestamp("2025-12-26 10:00"), title="End Date", group="Date Range")//10:00 | DL6: endDate = input.time(timestamp("2025-12-29 10:00"), title="End Date", group="Date Range")//10:00 | DM6: endDate = input.time(timestamp("2025-12-31 10:00"), title="End Date", group="Date Range")//10:00 | DN6: endDate = input.time(timestamp("2025-12-31 10:00"), title="End Date", group="Date Range")//10:00 | DO6: endDate = input.time(timestamp("2026-01-01 10:00"), title="End Date", group="Date Range")//10:00 | DP6: endDate = input.time(timestamp("2026-01-02 10:00"), title="End Date", group="Date Range")//10:00 | DQ6: endDate = input.time(timestamp("2026-01-05 10:00"), title="End Date", group="Date Range")//10:00 | DS6: endDate = input.time(timestamp("2026-01-08 10:00"), title="End Date", group="Date Range")//10:00 | DT6: endDate = input.time(timestamp("2026-01-08 10:00"), title="End Date", group="Date Range")//10:00 | DU6: endDate = input.time(timestamp("2026-01-09 10:00"), title="End Date", group="Date Range")//10:00 | DV6: endDate = input.time(timestamp("2026-01-12 10:00"), title="End Date", group="Date Range")//10:00 | DW6: endDate = input.time(timestamp("2026-01-13 10:00"), title="End Date", group="Date Range")//10:00 | DZ6: endDate = input.time(timestamp("2026-01-19 10:00"), title="End Date", group="Date Range")//10:00 | EA6: endDate = input.time(timestamp("2026-01-20 10:00"), title="End Date", group="Date Range")//10:00 | EE6: endDate = input.time(timestamp("2026-01-28 10:00"), title="End Date", group="Date Range")//10:00 | EF6: endDate = input.time(timestamp("2026-01-29 10:00"), title="End Date", group="Date Range")//10:00 | EG6: endDate = input.time(timestamp("2026-01-30 10:00"), title="End Date", group="Date Range")//10:00 | EH6: endDate = input.time(timestamp("2026-01-30 10:00"), title="End Date", group="Date Range")//10:00 | EI6: endDate = input.time(timestamp("2026-02-02 10:00"), title="End Date", group="Date Range")//10:00 | EJ6: endDate = input.time(timestamp("2026-02-03 10:00"), title="End Date", group="Date Range")//10:00 | EL6: endDate = input.time(timestamp("2026-02-04 10:00"), title="End Date", group="Date Range")//10:00 | EM6: endDate = input.time(timestamp("2026-02-05 10:00"), title="End Date", group="Date Range")//10:00 | EP6: endDate = input.time(timestamp("2026-02-09 10:00"), title="End Date", group="Date Range")//10:00 | EQ6: endDate = input.time(timestamp("2026-02-10 10:00"), title="End Date", group="Date Range")//10:00 | ER6: endDate = input.time(timestamp("2026-02-11 10:00"), title="End Date", group="Date Range")//10:00 | EU6: endDate = input.time(timestamp("2026-02-16 10:00"), title="End Date", group="Date Range")//10:00 | EV6: endDate = input.time(timestamp("2026-02-17 10:00"), title="End Date", group="Date Range")//10:00 | EW6: endDate = input.time(timestamp("2026-02-18 10:00"), title="End Date", group="Date Range")//10:00 | EX6: endDate = input.time(timestamp("2026-02-19 10:00"), title="End Date", group="Date Range")//10:00 | EY6: endDate = input.time(timestamp("2026-02-20 10:00"), title="End Date", group="Date Range")//10:00 | EZ6: endDate = input.time(timestamp("2026-02-23 10:00"), title="End Date", group="Date Range")//10:00 | FA6: endDate = input.time(timestamp("2026-02-24 10:00"), title="End Date", group="Date Range")//10:00 | FB6: endDate = input.time(timestamp("2026-02-25 10:00"), title="End Date", group="Date Range")//10:00 | FC6: endDate = input.time(timestamp("2026-02-26 10:00"), title="End Date", group="Date Range")//10:00
